Короткий ответ: **нет, они не равноценны**:

Разница в том, что если ошибка произойдёт в `f1`, то она будет обработана в `.catch` в этом примере:

```js run
promise
  .then(f1)
  .catch(f2);
```

...но не в этом:

```js run
promise
  .then(f1, f2);
```

Так как ошибка передастся по цепочке, но во втором примере цепочка завершается на `f1`.

Другими словами, `.then` передаёт результат или ошибку следующему блоку `.then/catch`. Таким образом, в первом примере в цепочке далее имеется блок `catch`, а во втором -- нет, так что ошибка останется необработанной.
